<?xml version="1.0"?>
<robot xmlns:xacro="http://www.ros.org/wiki/xacro" name="odrive_robot">

  <xacro:arg name="enable_FL_hip_joint"  default="false" />
  <xacro:arg name="enable_FR_hip_joint"  default="false" />
  <xacro:arg name="enable_RL_hip_joint"  default="false" />
  <xacro:arg name="enable_RR_hip_joint"  default="false" />
  <xacro:arg name="enable_FL_thigh_joint"  default="false" />
  <xacro:arg name="enable_FR_thigh_joint"  default="false" />
  <xacro:arg name="enable_RL_thigh_joint"  default="false" />
  <xacro:arg name="enable_RR_thigh_joint"  default="false" />
  <xacro:arg name="enable_FL_calf_joint"  default="false" />
  <xacro:arg name="enable_FR_calf_joint"  default="false" />
  <xacro:arg name="enable_RL_calf_joint"  default="false" />
  <xacro:arg name="enable_RR_calf_joint"  default="false" />

  <xacro:arg name="front_hip_serial" default="20763599524B" />
  <xacro:arg name="front_thigh_serial" default="2081356E524B" />
  <xacro:arg name="front_calf_serial" default="205B39814D4D" />
  <xacro:arg name="rear_hip_serial"  default="208339814D4D" />
  <xacro:arg name="rear_thigh_serial" default="345735573033" />
  <xacro:arg name="rear_calf_serial"  default="346035533033" />

  <xacro:include filename="$(find cerberus_description)/urdf/odrive.ros2_control.xacro" />

  <link name="world" />

  <xacro:if value="$(arg enable_FL_hip_joint)">
    <link name="FL_hip_link" />
    <joint name="FL_hip_joint" type="continuous">
      <parent link="world"/>
      <child link="FL_hip_link"/>
      <axis xyz="0 0 1"/>
    </joint>
  </xacro:if>

  <xacro:if value="$(arg enable_FR_hip_joint)">
    <link name="FR_hip_link" />
    <joint name="FR_hip_joint" type="continuous">
      <parent link="world"/>
      <child link="FR_hip_link"/>
      <axis xyz="0 0 1"/>
    </joint>
  </xacro:if>

  <xacro:if value="$(arg enable_RL_hip_joint)">
    <link name="RL_hip_link" />
    <joint name="RL_hip_joint" type="continuous">
      <parent link="world"/>
      <child link="RL_hip_link"/>
      <axis xyz="0 0 1"/>
    </joint>
  </xacro:if>

  <xacro:if value="$(arg enable_RR_hip_joint)">
    <link name="RR_hip_link" />
    <joint name="RR_hip_joint" type="continuous">
      <parent link="world"/>
      <child link="RR_hip_link"/>
      <axis xyz="0 0 1"/>
    </joint>
  </xacro:if>

  <xacro:if value="$(arg enable_FL_thigh_joint)">
    <link name="FL_thigh_link" />
    <joint name="FL_thigh_joint" type="continuous">
      <parent link="world"/>
      <child link="FL_thigh_link"/>
      <axis xyz="0 0 1"/>
    </joint>
  </xacro:if>

  <xacro:if value="$(arg enable_FR_thigh_joint)">
    <link name="FR_thigh_link" />
    <joint name="FR_thigh_joint" type="continuous">
      <parent link="world"/>
      <child link="FR_thigh_link"/>
      <axis xyz="0 0 1"/>
    </joint>
  </xacro:if>

  <xacro:if value="$(arg enable_RL_thigh_joint)">
    <link name="RL_thigh_link" />
    <joint name="RL_thigh_joint" type="continuous">
      <parent link="world"/>
      <child link="RL_thigh_link"/>
      <axis xyz="0 0 1"/>
    </joint>
  </xacro:if>

  <xacro:if value="$(arg enable_RR_thigh_joint)">
    <link name="RR_thigh_link" />
    <joint name="RR_thigh_joint" type="continuous">
      <parent link="world"/>
      <child link="RR_thigh_link"/>
      <axis xyz="0 0 1"/>
    </joint>
  </xacro:if>

  <xacro:if value="$(arg enable_FL_calf_joint)">
    <link name="FL_calf_link" />
    <joint name="FL_calf_joint" type="continuous">
      <parent link="world"/>
      <child link="FL_calf_link"/>
      <axis xyz="0 0 1"/>
    </joint>
  </xacro:if>

  <xacro:if value="$(arg enable_FR_calf_joint)">
    <link name="FR_calf_link" />
    <joint name="FR_calf_joint" type="continuous">
      <parent link="world"/>
      <child link="FR_calf_link"/>
      <axis xyz="0 0 1"/>
    </joint>
  </xacro:if>

  <xacro:if value="$(arg enable_RL_calf_joint)">
    <link name="RL_calf_link" />
    <joint name="RL_calf_joint" type="continuous">
      <parent link="world"/>
      <child link="RL_calf_link"/>
      <axis xyz="0 0 1"/>
    </joint>
  </xacro:if>

  <xacro:if value="$(arg enable_RR_calf_joint)">
    <link name="RR_calf_link" />
    <joint name="RR_calf_joint" type="continuous">
      <parent link="world"/>
      <child link="RR_calf_link"/>
      <axis xyz="0 0 1"/>
    </joint>
  </xacro:if>

  <xacro:odrive_ros2_control
    name="front_hip_ros2_control"
    sensor_name="odrv0"
    serial_number="$(arg front_hip_serial)"
    joint0_name="FL_hip_joint" enable_joint0="$(arg enable_FL_hip_joint)"
    joint1_name="FR_hip_joint" enable_joint1="$(arg enable_FR_hip_joint)" />

  <xacro:odrive_ros2_control
    name="front_thigh_ros2_control"
    sensor_name="odrv1"
    serial_number="$(arg front_thigh_serial)"
    joint0_name="FL_thigh_joint" enable_joint0="$(arg enable_FL_thigh_joint)"
    joint1_name="FR_thigh_joint" enable_joint1="$(arg enable_FR_thigh_joint)" />

  <xacro:odrive_ros2_control
    name="front_calf_ros2_control"
    sensor_name="odrv2"
    serial_number="$(arg front_calf_serial)"
    joint0_name="FL_calf_joint" enable_joint0="$(arg enable_FL_calf_joint)"
    joint1_name="FR_calf_joint" enable_joint1="$(arg enable_FR_calf_joint)" />

  <xacro:odrive_ros2_control
    name="rear_hip_ros2_control"
    sensor_name="odrv3"
    serial_number="$(arg rear_hip_serial)"
    joint0_name="RL_hip_joint" enable_joint0="$(arg enable_RL_hip_joint)"
    joint1_name="RR_hip_joint" enable_joint1="$(arg enable_RR_hip_joint)" />

  <xacro:odrive_ros2_control
    name="rear_thigh_ros2_control"
    sensor_name="odrv4"
    serial_number="$(arg rear_thigh_serial)"
    joint0_name="RL_thigh_joint" enable_joint0="$(arg enable_RL_thigh_joint)"
    joint1_name="RR_thigh_joint" enable_joint1="$(arg enable_RR_thigh_joint)" />

  <xacro:odrive_ros2_control
    name="rear_calf_ros2_control"
    sensor_name="odrv5"
    serial_number="$(arg rear_calf_serial)"
    joint0_name="RL_calf_joint" enable_joint0="$(arg enable_RL_calf_joint)"
    joint1_name="RR_calf_joint" enable_joint1="$(arg enable_RR_calf_joint)" />

</robot>
