<?xml version="1.0" ?>
<!-- =================================================================================== -->
<!-- |    This document was autogenerated by xacro from cerbiboi.urdf.xacro            | -->
<!-- |    EDITING THIS FILE BY HAND IS NOT RECOMMENDED                                 | -->
<!-- =================================================================================== -->
<robot name="Cerberus">
  <!--
    <link name="world" />
    <joint name="world_joint" type="fixed">
        <parent link="world" />
        <child link="base_link" />
    </joint>
    -->
  <link name="base_link">
    <visual>
      <geometry>
        <box size="0.45 0.282 0.2"/>
      </geometry>
      <material name="blue">
        <color rgba="0.3 0.3 0.8 1.0"/>
      </material>
    </visual>
    <collision>
      <geometry>
        <box size="0.45 0.282 0.2"/>
      </geometry>
    </collision>
    <visual>
      <origin xyz="0 0 0.077"/>
      <geometry>
        <box size="0.9 0.019 0.03"/>
      </geometry>
      <material name="blue">
        <color rgba="0.3 0.3 0.8 1.0"/>
      </material>
    </visual>
    <collision>
      <origin xyz="0 0 0.077"/>
      <geometry>
        <box size="0.9 0.019 0.03"/>
      </geometry>
    </collision>
    <inertial>
      <mass value="5.0"/>
      <inertia ixx="0.04980166667" ixy="0.0" ixz="0.0" iyy="0.1010416667" iyz="0.0" izz="0.11751"/>
    </inertial>
  </link>
  <joint name="FL_leg_connector" type="fixed">
    <parent link="base_link"/>
    <child link="FL_gearbox_shoulder"/>
    <origin rpy="0 1.5707963267948966 0" xyz="0.275 0.08 0"/>
  </joint>
  <link name="FL_gearbox_shoulder">
    <visual>
      <geometry>
        <cylinder length="0.1" radius="0.055"/>
      </geometry>
      <material name="purple">
        <color rgba="0.43 0.27 0.52 1"/>
      </material>
    </visual>
    <collision>
      <geometry>
        <cylinder length="0.1" radius="0.055"/>
      </geometry>
    </collision>
    <inertial>
      <mass value="0.95"/>
      <inertia ixx="0.01" ixy="0" ixz="0" iyy="0.01" iyz="0" izz="0.01"/>
    </inertial>
  </link>
  <joint name="FL_hip_joint" type="revolute">
    <parent link="FL_gearbox_shoulder"/>
    <child link="FL_gearbox_shoulder2"/>
    <origin rpy="1.5707963267948963 0 0" xyz="0 0 0.1"/>
    <axis xyz="0 1 0"/>
    <limit effort="45" lower="-1.57" upper="1.57" velocity="45"/>
  </joint>
  <link name="FL_gearbox_shoulder2">
    <visual>
      <origin xyz="0 0 -0.0175"/>
      <geometry>
        <cylinder length="0.1" radius="0.055"/>
      </geometry>
      <material name="purple">
        <color rgba="0.43 0.27 0.52 1"/>
      </material>
    </visual>
    <collision>
      <origin xyz="0 0 -0.0175"/>
      <geometry>
        <cylinder length="0.1" radius="0.055"/>
      </geometry>
    </collision>
    <inertial>
      <mass value="0.95"/>
      <inertia ixx="0.01" ixy="0" ixz="0" iyy="0.01" iyz="0" izz="0.01"/>
    </inertial>
  </link>
  <joint name="FL_thigh_joint" type="revolute">
    <parent link="FL_gearbox_shoulder2"/>
    <child link="FL_upper_leg"/>
    <origin rpy="1.5707963267948963 0 1.5707963267948966" xyz="0 0 -0.1205"/>
    <axis xyz="0 1 0"/>
    <limit effort="45" lower="-2.094395102" upper="1.047197551" velocity="45"/>
  </joint>
  <link name="FL_outer_gearbox">
    <visual>
      <origin xyz="0 0 -0.0175"/>
      <geometry>
        <cylinder length="0.1" radius="0.055"/>
      </geometry>
      <material name="purple">
        <color rgba="0.43 0.27 0.52 1"/>
      </material>
    </visual>
    <collision>
      <origin xyz="0 0 -0.0175"/>
      <geometry>
        <cylinder length="0.1" radius="0.055"/>
      </geometry>
    </collision>
    <inertial>
      <mass value="0.95"/>
      <inertia ixx="0.01" ixy="0" ixz="0" iyy="0.01" iyz="0" izz="0.01"/>
    </inertial>
  </link>
  <joint name="FL_shoulder_gearbox" type="fixed">
    <parent link="FL_upper_leg"/>
    <child link="FL_outer_gearbox"/>
    <origin rpy="1.5707963267948963 0 0" xyz="0 -0.07 0"/>
  </joint>
  <link name="FL_upper_leg">
    <visual>
      <origin xyz="0 0 0.15"/>
      <geometry>
        <cylinder length="0.3" radius="0.038"/>
      </geometry>
      <material name="purple">
        <color rgba="0.43 0.27 0.52 1"/>
      </material>
    </visual>
    <collision>
      <origin xyz="0 0 0.15"/>
      <geometry>
        <cylinder length="0.3" radius="0.038"/>
      </geometry>
    </collision>
    <inertial>
      <mass value="0.55"/>
      <inertia ixx="0.01" ixy="0" ixz="0" iyy="0.01" iyz="0" izz="0.01"/>
    </inertial>
  </link>
  <joint name="FL_calf_joint" type="revolute">
    <parent link="FL_upper_leg"/>
    <child link="FL_lower_leg"/>
    <origin rpy="0 1.5707963267948966 0" xyz="0 0 0.3"/>
    <axis xyz="0 1 0"/>
    <limit effort="45" lower="-0.5235987756" upper="1.047197551" velocity="45"/>
  </joint>
  <link name="FL_lower_leg">
    <visual>
      <origin xyz="0 0 0.15"/>
      <geometry>
        <cylinder length="0.3" radius="0.026"/>
      </geometry>
      <material name="purple">
        <color rgba="0.43 0.27 0.52 1"/>
      </material>
    </visual>
    <collision>
      <origin xyz="0 0 0.15"/>
      <geometry>
        <cylinder length="0.3" radius="0.026"/>
      </geometry>
    </collision>
    <inertial>
      <mass value="0.4"/>
      <inertia ixx="0.01" ixy="0" ixz="0" iyy="0.01" iyz="0" izz="0.01"/>
    </inertial>
  </link>
  <joint name="FL_foot_fixed" type="fixed">
    <parent link="FL_lower_leg"/>
    <child link="FL_sock"/>
    <origin rpy="1.5707963267948966 0 0" xyz="0 0 0.3"/>
  </joint>
  <link name="FL_foot">
    <visual>
      <origin xyz="0 0 0"/>
      <geometry>
        <cylinder length="0.025" radius="0.030"/>
      </geometry>
      <material name="kinda_blue">
        <color rgba="0.27 0.27 0.52 1"/>
      </material>
    </visual>
    <visual>
      <origin xyz="0 0 0.0125"/>
      <geometry>
        <sphere radius="0.030"/>
      </geometry>
      <material name="kinda_blue">
        <color rgba="0.27 0.27 0.52 1"/>
      </material>
    </visual>
    <visual>
      <origin xyz="0 0 -0.0125"/>
      <geometry>
        <sphere radius="0.030"/>
      </geometry>
      <material name="kinda_blue">
        <color rgba="0.27 0.27 0.52 1"/>
      </material>
    </visual>
    <collision>
      <origin xyz="0 0 0"/>
      <geometry>
        <cylinder length="0.025" radius="0.030"/>
      </geometry>
    </collision>
    <collision>
      <origin xyz="0 0 0.0125"/>
      <geometry>
        <sphere radius="0.030"/>
      </geometry>
    </collision>
    <collision>
      <origin xyz="0 0 -0.0125"/>
      <geometry>
        <sphere radius="0.030"/>
      </geometry>
    </collision>
    <inertial>
      <mass value="0.1"/>
      <inertia ixx="0.01" ixy="0" ixz="0" iyy="0.01" iyz="0" izz="0.01"/>
    </inertial>
  </link>
  <joint name="FR_leg_connector" type="fixed">
    <parent link="base_link"/>
    <child link="FR_gearbox_shoulder"/>
    <origin rpy="3.14159265 -1.5707963267948966 0" xyz="0.275 -0.08 0"/>
  </joint>
  <link name="FR_gearbox_shoulder">
    <visual>
      <geometry>
        <cylinder length="0.1" radius="0.055"/>
      </geometry>
      <material name="purple">
        <color rgba="0.43 0.27 0.52 1"/>
      </material>
    </visual>
    <collision>
      <geometry>
        <cylinder length="0.1" radius="0.055"/>
      </geometry>
    </collision>
    <inertial>
      <mass value="0.95"/>
      <inertia ixx="0.01" ixy="0" ixz="0" iyy="0.01" iyz="0" izz="0.01"/>
    </inertial>
  </link>
  <joint name="FR_hip_joint" type="revolute">
    <parent link="FR_gearbox_shoulder"/>
    <child link="FR_gearbox_shoulder2"/>
    <origin rpy="1.5707963267948963 0 0" xyz="0 0 0.1"/>
    <axis xyz="0 -1 0"/>
    <limit effort="45" lower="-1.57" upper="1.57" velocity="45"/>
  </joint>
  <link name="FR_gearbox_shoulder2">
    <visual>
      <origin xyz="0 0 -0.0175"/>
      <geometry>
        <cylinder length="0.1" radius="0.055"/>
      </geometry>
      <material name="purple">
        <color rgba="0.43 0.27 0.52 1"/>
      </material>
    </visual>
    <collision>
      <origin xyz="0 0 -0.0175"/>
      <geometry>
        <cylinder length="0.1" radius="0.055"/>
      </geometry>
    </collision>
    <inertial>
      <mass value="0.95"/>
      <inertia ixx="0.01" ixy="0" ixz="0" iyy="0.01" iyz="0" izz="0.01"/>
    </inertial>
  </link>
  <joint name="FR_thigh_joint" type="revolute">
    <parent link="FR_gearbox_shoulder2"/>
    <child link="FR_upper_leg"/>
    <origin rpy="1.5707963267948963 0 -1.5707963267948966" xyz="0 0 -0.1205"/>
    <axis xyz="0 -1 0"/>
    <limit effort="45" lower="-2.094395102" upper="1.047197551" velocity="45"/>
  </joint>
  <link name="FR_outer_gearbox">
    <visual>
      <origin xyz="0 0 -0.0175"/>
      <geometry>
        <cylinder length="0.1" radius="0.055"/>
      </geometry>
      <material name="purple">
        <color rgba="0.43 0.27 0.52 1"/>
      </material>
    </visual>
    <collision>
      <origin xyz="0 0 -0.0175"/>
      <geometry>
        <cylinder length="0.1" radius="0.055"/>
      </geometry>
    </collision>
    <inertial>
      <mass value="0.95"/>
      <inertia ixx="0.01" ixy="0" ixz="0" iyy="0.01" iyz="0" izz="0.01"/>
    </inertial>
  </link>
  <joint name="FR_shoulder_gearbox" type="fixed">
    <parent link="FR_upper_leg"/>
    <child link="FR_outer_gearbox"/>
    <origin rpy="1.5707963267948963 0 0" xyz="0 -0.07 0"/>
  </joint>
  <link name="FR_upper_leg">
    <visual>
      <origin xyz="0 0 0.15"/>
      <geometry>
        <cylinder length="0.3" radius="0.038"/>
      </geometry>
      <material name="purple">
        <color rgba="0.43 0.27 0.52 1"/>
      </material>
    </visual>
    <collision>
      <origin xyz="0 0 0.15"/>
      <geometry>
        <cylinder length="0.3" radius="0.038"/>
      </geometry>
    </collision>
    <inertial>
      <mass value="0.55"/>
      <inertia ixx="0.01" ixy="0" ixz="0" iyy="0.01" iyz="0" izz="0.01"/>
    </inertial>
  </link>
  <joint name="FR_calf_joint" type="revolute">
    <parent link="FR_upper_leg"/>
    <child link="FR_lower_leg"/>
    <origin rpy="0 -1.5707963267948966 0" xyz="0 0 0.3"/>
    <axis xyz="0 -1 0"/>
    <limit effort="45" lower="-0.5235987756" upper="1.047197551" velocity="45"/>
  </joint>
  <link name="FR_lower_leg">
    <visual>
      <origin xyz="0 0 0.15"/>
      <geometry>
        <cylinder length="0.3" radius="0.026"/>
      </geometry>
      <material name="purple">
        <color rgba="0.43 0.27 0.52 1"/>
      </material>
    </visual>
    <collision>
      <origin xyz="0 0 0.15"/>
      <geometry>
        <cylinder length="0.3" radius="0.026"/>
      </geometry>
    </collision>
    <inertial>
      <mass value="0.4"/>
      <inertia ixx="0.01" ixy="0" ixz="0" iyy="0.01" iyz="0" izz="0.01"/>
    </inertial>
  </link>
  <joint name="FR_foot_fixed" type="fixed">
    <parent link="FR_lower_leg"/>
    <child link="FR_sock"/>
    <origin rpy="1.5707963267948966 0 0" xyz="0 0 0.3"/>
  </joint>
  <link name="FR_foot">
    <visual>
      <origin xyz="0 0 0"/>
      <geometry>
        <cylinder length="0.025" radius="0.030"/>
      </geometry>
      <material name="kinda_blue">
        <color rgba="0.27 0.27 0.52 1"/>
      </material>
    </visual>
    <visual>
      <origin xyz="0 0 0.0125"/>
      <geometry>
        <sphere radius="0.030"/>
      </geometry>
      <material name="kinda_blue">
        <color rgba="0.27 0.27 0.52 1"/>
      </material>
    </visual>
    <visual>
      <origin xyz="0 0 -0.0125"/>
      <geometry>
        <sphere radius="0.030"/>
      </geometry>
      <material name="kinda_blue">
        <color rgba="0.27 0.27 0.52 1"/>
      </material>
    </visual>
    <collision>
      <origin xyz="0 0 0"/>
      <geometry>
        <cylinder length="0.025" radius="0.030"/>
      </geometry>
    </collision>
    <collision>
      <origin xyz="0 0 0.0125"/>
      <geometry>
        <sphere radius="0.030"/>
      </geometry>
    </collision>
    <collision>
      <origin xyz="0 0 -0.0125"/>
      <geometry>
        <sphere radius="0.030"/>
      </geometry>
    </collision>
    <inertial>
      <mass value="0.1"/>
      <inertia ixx="0.01" ixy="0" ixz="0" iyy="0.01" iyz="0" izz="0.01"/>
    </inertial>
  </link>
  <joint name="RL_leg_connector" type="fixed">
    <parent link="base_link"/>
    <child link="RL_gearbox_shoulder"/>
    <origin rpy="0 1.5707963267948966 0" xyz="-0.275 0.08 0"/>
  </joint>
  <link name="RL_gearbox_shoulder">
    <visual>
      <geometry>
        <cylinder length="0.1" radius="0.055"/>
      </geometry>
      <material name="purple">
        <color rgba="0.43 0.27 0.52 1"/>
      </material>
    </visual>
    <collision>
      <geometry>
        <cylinder length="0.1" radius="0.055"/>
      </geometry>
    </collision>
    <inertial>
      <mass value="0.95"/>
      <inertia ixx="0.01" ixy="0" ixz="0" iyy="0.01" iyz="0" izz="0.01"/>
    </inertial>
  </link>
  <joint name="RL_hip_joint" type="revolute">
    <parent link="RL_gearbox_shoulder"/>
    <child link="RL_gearbox_shoulder2"/>
    <origin rpy="1.5707963267948963 0 0" xyz="0 0 -0.1"/>
    <axis xyz="0 1 0"/>
    <limit effort="45" lower="-1.57" upper="1.57" velocity="45"/>
  </joint>
  <link name="RL_gearbox_shoulder2">
    <visual>
      <origin xyz="0 0 -0.0175"/>
      <geometry>
        <cylinder length="0.1" radius="0.055"/>
      </geometry>
      <material name="purple">
        <color rgba="0.43 0.27 0.52 1"/>
      </material>
    </visual>
    <collision>
      <origin xyz="0 0 -0.0175"/>
      <geometry>
        <cylinder length="0.1" radius="0.055"/>
      </geometry>
    </collision>
    <inertial>
      <mass value="0.95"/>
      <inertia ixx="0.01" ixy="0" ixz="0" iyy="0.01" iyz="0" izz="0.01"/>
    </inertial>
  </link>
  <joint name="RL_thigh_joint" type="revolute">
    <parent link="RL_gearbox_shoulder2"/>
    <child link="RL_upper_leg"/>
    <origin rpy="1.5707963267948963 0 1.5707963267948966" xyz="0 0 -0.1205"/>
    <axis xyz="0 1 0"/>
    <limit effort="45" lower="-2.094395102" upper="1.047197551" velocity="45"/>
  </joint>
  <link name="RL_outer_gearbox">
    <visual>
      <origin xyz="0 0 -0.0175"/>
      <geometry>
        <cylinder length="0.1" radius="0.055"/>
      </geometry>
      <material name="purple">
        <color rgba="0.43 0.27 0.52 1"/>
      </material>
    </visual>
    <collision>
      <origin xyz="0 0 -0.0175"/>
      <geometry>
        <cylinder length="0.1" radius="0.055"/>
      </geometry>
    </collision>
    <inertial>
      <mass value="0.95"/>
      <inertia ixx="0.01" ixy="0" ixz="0" iyy="0.01" iyz="0" izz="0.01"/>
    </inertial>
  </link>
  <joint name="RL_shoulder_gearbox" type="fixed">
    <parent link="RL_upper_leg"/>
    <child link="RL_outer_gearbox"/>
    <origin rpy="1.5707963267948963 0 0" xyz="0 -0.07 0"/>
  </joint>
  <link name="RL_upper_leg">
    <visual>
      <origin xyz="0 0 0.15"/>
      <geometry>
        <cylinder length="0.3" radius="0.038"/>
      </geometry>
      <material name="purple">
        <color rgba="0.43 0.27 0.52 1"/>
      </material>
    </visual>
    <collision>
      <origin xyz="0 0 0.15"/>
      <geometry>
        <cylinder length="0.3" radius="0.038"/>
      </geometry>
    </collision>
    <inertial>
      <mass value="0.55"/>
      <inertia ixx="0.01" ixy="0" ixz="0" iyy="0.01" iyz="0" izz="0.01"/>
    </inertial>
  </link>
  <joint name="RL_calf_joint" type="revolute">
    <parent link="RL_upper_leg"/>
    <child link="RL_lower_leg"/>
    <origin rpy="0 1.5707963267948966 0" xyz="0 0 0.3"/>
    <axis xyz="0 1 0"/>
    <limit effort="45" lower="-0.5235987756" upper="1.047197551" velocity="45"/>
  </joint>
  <link name="RL_lower_leg">
    <visual>
      <origin xyz="0 0 0.15"/>
      <geometry>
        <cylinder length="0.3" radius="0.026"/>
      </geometry>
      <material name="purple">
        <color rgba="0.43 0.27 0.52 1"/>
      </material>
    </visual>
    <collision>
      <origin xyz="0 0 0.15"/>
      <geometry>
        <cylinder length="0.3" radius="0.026"/>
      </geometry>
    </collision>
    <inertial>
      <mass value="0.4"/>
      <inertia ixx="0.01" ixy="0" ixz="0" iyy="0.01" iyz="0" izz="0.01"/>
    </inertial>
  </link>
  <joint name="RL_foot_fixed" type="fixed">
    <parent link="RL_lower_leg"/>
    <child link="RL_sock"/>
    <origin rpy="1.5707963267948966 0 0" xyz="0 0 0.3"/>
  </joint>
  <link name="RL_foot">
    <visual>
      <origin xyz="0 0 0"/>
      <geometry>
        <cylinder length="0.025" radius="0.030"/>
      </geometry>
      <material name="kinda_blue">
        <color rgba="0.27 0.27 0.52 1"/>
      </material>
    </visual>
    <visual>
      <origin xyz="0 0 0.0125"/>
      <geometry>
        <sphere radius="0.030"/>
      </geometry>
      <material name="kinda_blue">
        <color rgba="0.27 0.27 0.52 1"/>
      </material>
    </visual>
    <visual>
      <origin xyz="0 0 -0.0125"/>
      <geometry>
        <sphere radius="0.030"/>
      </geometry>
      <material name="kinda_blue">
        <color rgba="0.27 0.27 0.52 1"/>
      </material>
    </visual>
    <collision>
      <origin xyz="0 0 0"/>
      <geometry>
        <cylinder length="0.025" radius="0.030"/>
      </geometry>
    </collision>
    <collision>
      <origin xyz="0 0 0.0125"/>
      <geometry>
        <sphere radius="0.030"/>
      </geometry>
    </collision>
    <collision>
      <origin xyz="0 0 -0.0125"/>
      <geometry>
        <sphere radius="0.030"/>
      </geometry>
    </collision>
    <inertial>
      <mass value="0.1"/>
      <inertia ixx="0.01" ixy="0" ixz="0" iyy="0.01" iyz="0" izz="0.01"/>
    </inertial>
  </link>
  <joint name="RR_leg_connector" type="fixed">
    <parent link="base_link"/>
    <child link="RR_gearbox_shoulder"/>
    <origin rpy="3.14159265 -1.5707963267948966 0" xyz="-0.275 -0.08 0"/>
  </joint>
  <link name="RR_gearbox_shoulder">
    <visual>
      <geometry>
        <cylinder length="0.1" radius="0.055"/>
      </geometry>
      <material name="purple">
        <color rgba="0.43 0.27 0.52 1"/>
      </material>
    </visual>
    <collision>
      <geometry>
        <cylinder length="0.1" radius="0.055"/>
      </geometry>
    </collision>
    <inertial>
      <mass value="0.95"/>
      <inertia ixx="0.01" ixy="0" ixz="0" iyy="0.01" iyz="0" izz="0.01"/>
    </inertial>
  </link>
  <joint name="RR_hip_joint" type="revolute">
    <parent link="RR_gearbox_shoulder"/>
    <child link="RR_gearbox_shoulder2"/>
    <origin rpy="1.5707963267948963 0 0" xyz="0 0 -0.1"/>
    <axis xyz="0 -1 0"/>
    <limit effort="45" lower="-1.57" upper="1.57" velocity="45"/>
  </joint>
  <link name="RR_gearbox_shoulder2">
    <visual>
      <origin xyz="0 0 -0.0175"/>
      <geometry>
        <cylinder length="0.1" radius="0.055"/>
      </geometry>
      <material name="purple">
        <color rgba="0.43 0.27 0.52 1"/>
      </material>
    </visual>
    <collision>
      <origin xyz="0 0 -0.0175"/>
      <geometry>
        <cylinder length="0.1" radius="0.055"/>
      </geometry>
    </collision>
    <inertial>
      <mass value="0.95"/>
      <inertia ixx="0.01" ixy="0" ixz="0" iyy="0.01" iyz="0" izz="0.01"/>
    </inertial>
  </link>
  <joint name="RR_thigh_joint" type="revolute">
    <parent link="RR_gearbox_shoulder2"/>
    <child link="RR_upper_leg"/>
    <origin rpy="1.5707963267948963 0 -1.5707963267948966" xyz="0 0 -0.1205"/>
    <axis xyz="0 -1 0"/>
    <limit effort="45" lower="-2.094395102" upper="1.047197551" velocity="45"/>
  </joint>
  <link name="RR_outer_gearbox">
    <visual>
      <origin xyz="0 0 -0.0175"/>
      <geometry>
        <cylinder length="0.1" radius="0.055"/>
      </geometry>
      <material name="purple">
        <color rgba="0.43 0.27 0.52 1"/>
      </material>
    </visual>
    <collision>
      <origin xyz="0 0 -0.0175"/>
      <geometry>
        <cylinder length="0.1" radius="0.055"/>
      </geometry>
    </collision>
    <inertial>
      <mass value="0.95"/>
      <inertia ixx="0.01" ixy="0" ixz="0" iyy="0.01" iyz="0" izz="0.01"/>
    </inertial>
  </link>
  <joint name="RR_shoulder_gearbox" type="fixed">
    <parent link="RR_upper_leg"/>
    <child link="RR_outer_gearbox"/>
    <origin rpy="1.5707963267948963 0 0" xyz="0 -0.07 0"/>
  </joint>
  <link name="RR_upper_leg">
    <visual>
      <origin xyz="0 0 0.15"/>
      <geometry>
        <cylinder length="0.3" radius="0.038"/>
      </geometry>
      <material name="purple">
        <color rgba="0.43 0.27 0.52 1"/>
      </material>
    </visual>
    <collision>
      <origin xyz="0 0 0.15"/>
      <geometry>
        <cylinder length="0.3" radius="0.038"/>
      </geometry>
    </collision>
    <inertial>
      <mass value="0.55"/>
      <inertia ixx="0.01" ixy="0" ixz="0" iyy="0.01" iyz="0" izz="0.01"/>
    </inertial>
  </link>
  <joint name="RR_calf_joint" type="revolute">
    <parent link="RR_upper_leg"/>
    <child link="RR_lower_leg"/>
    <origin rpy="0 -1.5707963267948966 0" xyz="0 0 0.3"/>
    <axis xyz="0 -1 0"/>
    <limit effort="45" lower="-0.5235987756" upper="1.047197551" velocity="45"/>
  </joint>
  <link name="RR_lower_leg">
    <visual>
      <origin xyz="0 0 0.15"/>
      <geometry>
        <cylinder length="0.3" radius="0.026"/>
      </geometry>
      <material name="purple">
        <color rgba="0.43 0.27 0.52 1"/>
      </material>
    </visual>
    <collision>
      <origin xyz="0 0 0.15"/>
      <geometry>
        <cylinder length="0.3" radius="0.026"/>
      </geometry>
    </collision>
    <inertial>
      <mass value="0.4"/>
      <inertia ixx="0.01" ixy="0" ixz="0" iyy="0.01" iyz="0" izz="0.01"/>
    </inertial>
  </link>
  <joint name="RR_foot_fixed" type="fixed">
    <parent link="RR_lower_leg"/>
    <child link="RR_sock"/>
    <origin rpy="1.5707963267948966 0 0" xyz="0 0 0.3"/>
  </joint>
  <link name="RR_foot">
    <visual>
      <origin xyz="0 0 0"/>
      <geometry>
        <cylinder length="0.025" radius="0.030"/>
      </geometry>
      <material name="kinda_blue">
        <color rgba="0.27 0.27 0.52 1"/>
      </material>
    </visual>
    <visual>
      <origin xyz="0 0 0.0125"/>
      <geometry>
        <sphere radius="0.030"/>
      </geometry>
      <material name="kinda_blue">
        <color rgba="0.27 0.27 0.52 1"/>
      </material>
    </visual>
    <visual>
      <origin xyz="0 0 -0.0125"/>
      <geometry>
        <sphere radius="0.030"/>
      </geometry>
      <material name="kinda_blue">
        <color rgba="0.27 0.27 0.52 1"/>
      </material>
    </visual>
    <collision>
      <origin xyz="0 0 0"/>
      <geometry>
        <cylinder length="0.025" radius="0.030"/>
      </geometry>
    </collision>
    <collision>
      <origin xyz="0 0 0.0125"/>
      <geometry>
        <sphere radius="0.030"/>
      </geometry>
    </collision>
    <collision>
      <origin xyz="0 0 -0.0125"/>
      <geometry>
        <sphere radius="0.030"/>
      </geometry>
    </collision>
    <inertial>
      <mass value="0.1"/>
      <inertia ixx="0.01" ixy="0" ixz="0" iyy="0.01" iyz="0" izz="0.01"/>
    </inertial>
  </link>
  <ros2_control name="IgnitionSystem" type="system">
    <hardware>
      <plugin>ign_ros2_control/IgnitionSystem</plugin>
    </hardware>
    <joint name="front_left_shoulder_connector">
      <command_interface name="position"/>
      <command_interface name="velocity"/>
      <state_interface name="position"/>
      <state_interface name="velocity"/>
    </joint>
    <joint name="front_left_shoulder_leg">
      <command_interface name="position"/>
      <command_interface name="velocity"/>
      <state_interface name="position"/>
      <state_interface name="velocity"/>
    </joint>
    <joint name="front_left_knee">
      <command_interface name="position"/>
      <command_interface name="velocity"/>
      <state_interface name="position"/>
      <state_interface name="velocity"/>
    </joint>
    <joint name="front_right_shoulder_connector">
      <command_interface name="position"/>
      <command_interface name="velocity"/>
      <state_interface name="position"/>
      <state_interface name="velocity"/>
    </joint>
    <joint name="front_right_shoulder_leg">
      <command_interface name="position"/>
      <command_interface name="velocity"/>
      <state_interface name="position"/>
      <state_interface name="velocity"/>
    </joint>
    <joint name="front_right_knee">
      <command_interface name="position"/>
      <command_interface name="velocity"/>
      <state_interface name="position"/>
      <state_interface name="velocity"/>
    </joint>
    <joint name="rear_left_shoulder_connector">
      <command_interface name="position"/>
      <command_interface name="velocity"/>
      <state_interface name="position"/>
      <state_interface name="velocity"/>
    </joint>
    <joint name="rear_left_shoulder_leg">
      <command_interface name="position"/>
      <command_interface name="velocity"/>
      <state_interface name="position"/>
      <state_interface name="velocity"/>
    </joint>
    <joint name="rear_left_knee">
      <command_interface name="position"/>
      <command_interface name="velocity"/>
      <state_interface name="position"/>
      <state_interface name="velocity"/>
    </joint>
    <joint name="rear_right_shoulder_connector">
      <command_interface name="position"/>
      <command_interface name="velocity"/>
      <state_interface name="position"/>
      <state_interface name="velocity"/>
    </joint>
    <joint name="rear_right_shoulder_leg">
      <command_interface name="position"/>
      <command_interface name="velocity"/>
      <state_interface name="position"/>
      <state_interface name="velocity"/>
    </joint>
    <joint name="rear_right_knee">
      <command_interface name="position"/>
      <command_interface name="velocity"/>
      <state_interface name="position"/>
      <state_interface name="velocity"/>
    </joint>
  </ros2_control>
  <gazebo>
    <plugin filename="ign_ros2_control-system" name="ign_ros2_control::IgnitionROS2ControlPlugin">
      <robot_param>robot_description</robot_param>
      <robot_param_node>robot_state_publisher</robot_param_node>
      <parameters>/home/v/Dev/Github/Cerberus/Control/cerberus_ws/install/cerberus_bringup/share/cerberus_bringup/config/cerberus.yaml</parameters>
    </plugin>
  </gazebo>
  <gazebo reference="base_link">
    <sensor name="imu_sensor" type="imu">
      <!-- Typically you need some sub-elements under <imu> -->
      <update_rate>50</update_rate>
      <always_on>true</always_on>
      <visualize>true</visualize>
      <topic>imu</topic>
      <imu>
        <noise type="none"/>
        <!-- or define noise parameters here -->
      </imu>
    </sensor>
  </gazebo>
</robot>
