<?xml version="1.0"?>
<robot xmlns:xacro="http://www.ros.org/wiki/xacro">
  <xacro:macro name="leg_macro"
    params="
      leg_name
      parent_link
      gearbox_offset
      connector_xyz:='0.35 0.08 0'
      connector_rpy:='0 1.5707963267948966 0'
      axis:='0 1 0'
      rot_off='0'
      shoulder_lower_limit='-1.57'
      shoulder_upper_limit='1.57'
      knee_rot_off='0'
      knee_lower_limit='-1.57'
      knee_upper_limit='1.57'
      effort='200'
      max_joint_velocity='2.0'
    ">
    <joint name="${leg_name}_leg_connector" type="fixed">
      <parent link="${parent_link}" />
      <child link="${leg_name}_gearbox_shoulder" />
      <origin xyz="${connector_xyz}" rpy="${connector_rpy}" />
    </joint>

    <link name="${leg_name}_gearbox_shoulder">
      <visual>
        <geometry>
          <cylinder radius="0.055" length="0.1" />
        </geometry>
        <material name="purple">
          <color rgba="0.43 0.27 0.52 1" />
        </material>
      </visual>
      <collision>
        <geometry>
          <cylinder radius="0.055" length="0.1" />
        </geometry>
      </collision>
      <inertial>
        <mass value="0.95" />
        <inertia ixx="0.001509" iyy="0.001509" izz="0.001438"
          ixy="0.0" ixz="0.0" iyz="0.0" />
      </inertial>

    </link>

    <joint name="${leg_name}_hip_joint" type="revolute">
      <parent link="${leg_name}_gearbox_shoulder" />
      <child link="${leg_name}_gearbox_shoulder2" />
      <origin xyz="0 0 ${gearbox_offset}" rpy="1.5707963267948963 0 0" />
      <axis xyz="${axis}" />
      <limit effort="${effort}" velocity="${max_joint_velocity}" lower="-1.57" upper="1.57" />
      <dynamics damping="0.9" friction="0.02" />
    </joint>

    <link name="${leg_name}_gearbox_shoulder2">
      <visual>
        <origin xyz="0 0 -0.0175" />
        <geometry>
          <cylinder radius="0.055" length="0.1" />
        </geometry>
        <material name="purple">
          <color rgba="0.43 0.27 0.52 1" />
        </material>
      </visual>
      <collision>
        <origin xyz="0 0 -0.0175" />
        <geometry>
          <cylinder radius="0.055" length="0.1" />
        </geometry>
      </collision>
      <inertial>
        <origin xyz="0 0 -0.0175" />
        <mass value="0.95" />
        <inertia ixx="0.001509" iyy="0.001509" izz="0.001438"
          ixy="0.0" ixz="0.0" iyz="0.0" />
      </inertial>
    </link>

    <joint name="${leg_name}_thigh_joint" type="revolute">
      <parent link="${leg_name}_gearbox_shoulder2" />
      <child link="${leg_name}_upper_leg" />
      <origin xyz="0 0 -0.1205" rpy="1.5707963267948963 0 ${rot_off}" />
      <axis xyz="${axis}" />
      <limit effort="${effort}" velocity="${max_joint_velocity}" lower="${shoulder_lower_limit}"
        upper="${shoulder_upper_limit}" />
        <dynamics damping="0.9" friction="0.02" />
    </joint>

    <link name="${leg_name}_outer_gearbox">
      <visual>
        <origin xyz="0 0 -0.0175" />
        <geometry>
          <cylinder radius="0.055" length="0.1" />
        </geometry>
        <material name="purple">
          <color rgba="0.43 0.27 0.52 1" />
        </material>
      </visual>
      <collision>
        <origin xyz="0 0 -0.0175" />
        <geometry>
          <cylinder radius="0.055" length="0.1" />
        </geometry>
      </collision>
      <inertial>
        <origin xyz="0 0 -0.0175" />
        <mass value="0.95" />
        <inertia ixx="0.001509" iyy="0.001509" izz="0.001438"
          ixy="0.0" ixz="0.0" iyz="0.0" />
      </inertial>
    </link>

    <joint name="${leg_name}_shoulder_gearbox" type="fixed">
      <parent link="${leg_name}_upper_leg" />
      <child link="${leg_name}_outer_gearbox" />
      <origin xyz="0 -0.07 0" rpy="1.5707963267948963 0 0" />
    </joint>

    <link name="${leg_name}_upper_leg">
      <visual>
        <origin xyz="0 0 0.15" />
        <geometry>
          <cylinder radius="0.038" length="0.3" />
        </geometry>
        <material name="purple">
          <color rgba="0.43 0.27 0.52 1" />
        </material>
      </visual>
      <collision>
        <origin xyz="0 0 0.15" />
        <geometry>
          <cylinder radius="0.038" length="0.3" />
        </geometry>
      </collision>
      <inertial>
        <origin xyz="0 0 0.15" />
        <mass value="0.55" />
        <inertia ixx="0.004327" iyy="0.004327" izz="0.000397"
          ixy="0.0" ixz="0.0" iyz="0.0" />
      </inertial>
    </link>

    <joint name="${leg_name}_calf_joint" type="revolute">
      <parent link="${leg_name}_upper_leg" />
      <child link="${leg_name}_lower_leg" />
      <origin xyz="0 0 0.3" rpy="0 ${knee_rot_off} 0" />
      <axis xyz="${axis}" />
      <limit effort="${effort}" velocity="${max_joint_velocity}" lower="${knee_lower_limit}"
        upper="${knee_upper_limit}" />
      <dynamics damping="0.9" friction="0.02" />
    </joint>


    <link name="${leg_name}_lower_leg">
      <visual>
        <origin xyz="0 0 0.15" />
        <geometry>
          <cylinder radius="0.026" length="0.3" />
        </geometry>
        <material name="purple">
          <color rgba="0.43 0.27 0.52 1" />
        </material>
      </visual>
      <collision>
        <origin xyz="0 0 0.15" />
        <geometry>
          <cylinder radius="0.026" length="0.3" />
        </geometry>
      </collision>
      <inertial>
        <origin xyz="0 0 0.15" />
        <mass value="0.4" />
        <inertia ixx="0.003068" iyy="0.003068" izz="0.000135"
          ixy="0.0" ixz="0.0" iyz="0.0" />
      </inertial>
    </link>

    <joint name="${leg_name}_foot_fixed" type="revolute">
      <parent link="${leg_name}_lower_leg" />
      <child link="${leg_name}_foot" />
      <origin xyz="0 0 0.3" rpy="1.5707963267948966 0 0" />
      <axis xyz="1 0 0" />
      <limit effort="0" velocity="0" lower="0"
        upper="0" />
    </joint>

    <link name="${leg_name}_foot">
      <visual>
        <origin xyz="0 0 0" />
        <geometry>
          <cylinder radius="0.030" length="0.025" />
        </geometry>
        <material name="kinda_blue">
          <color rgba="0.27 0.27 0.52 1" />
        </material>
      </visual>
      <visual>
        <origin xyz="0 0 0.0125" />
        <geometry>
          <sphere radius="0.030" />
        </geometry>
        <material name="kinda_blue">
          <color rgba="0.27 0.27 0.52 1" />
        </material>
      </visual>
      <visual>
        <origin xyz="0 0 -0.0125" />
        <geometry>
          <sphere radius="0.030" />
        </geometry>
        <material name="kinda_blue">
          <color rgba="0.27 0.27 0.52 1" />
        </material>
      </visual>

      <collision>
        <origin xyz="0 0 0" />
        <geometry>
          <cylinder radius="0.030" length="0.025" />
        </geometry>
      </collision>
      <collision>
        <origin xyz="0 0 0.0125" />
        <geometry>
          <sphere radius="0.030" />
        </geometry>
      </collision>
      <collision>
        <origin xyz="0 0 -0.0125" />
        <geometry>
          <sphere radius="0.030" />
        </geometry>
      </collision>


      <inertial>
        <mass value="0.1" />
        <inertia ixx="0.0000436" iyy="0.0000436" izz="0.000039"
          ixy="0.0" ixz="0.0" iyz="0.0" />
      </inertial>
    </link>

  </xacro:macro>
</robot>