<?xml version="1.0"?>
<robot xmlns:xacro="http://www.ros.org/wiki/xacro" name="odrive_robot">

  <!-- Arguments controlling whether each of the 12 joints is enabled -->
  <xacro:arg name="enable_joint0"  default="false" />
  <xacro:arg name="enable_joint1"  default="false" />

  <!-- Arguments for up to 6 ODrive boards (2 axes each) -->
  <xacro:arg name="odrive_1_serial" default="2081356E524B" />

  <!-- Include your custom ODrive xacro definition that handles up to two axes -->        
  <xacro:include filename="$(find cerberus_description)/urdf/odrive.ros2_control.xacro" />

  <!-- A world link to anchor everything -->
  <link name="world" />

  <!-- Define 12 links and 12 joints, each optional behind an enable_jointN check -->
  <xacro:if value="$(arg enable_joint0)">
    <link name="link0" />
    <joint name="joint0" type="continuous">
      <parent link="world"/>
      <child link="link0"/>
      <axis xyz="0 0 1"/>
    </joint>
  </xacro:if>

  <xacro:if value="$(arg enable_joint1)">
    <link name="link1" />
    <joint name="joint1" type="continuous">
      <parent link="world"/>
      <child link="link1"/>
      <axis xyz="0 0 1"/>
    </joint>
  </xacro:if>

  <xacro:odrive_ros2_control
    name="odrive1_ros2_control"
    sensor_name="odrv0"
    serial_number="$(arg odrive_1_serial)"
    joint0_name="joint0" enable_joint0="$(arg enable_joint0)"
    joint1_name="joint1" enable_joint1="$(arg enable_joint1)" />
</robot>
